[2024-08-25 17:34:04,777] {taskinstance.py:1159} INFO - Dependencies all met for <TaskInstance: dados_climaticos.extrai_dados scheduled__2022-10-10T00:00:00+00:00 [queued]>
[2024-08-25 17:34:04,785] {taskinstance.py:1159} INFO - Dependencies all met for <TaskInstance: dados_climaticos.extrai_dados scheduled__2022-10-10T00:00:00+00:00 [queued]>
[2024-08-25 17:34:04,785] {taskinstance.py:1356} INFO - 
--------------------------------------------------------------------------------
[2024-08-25 17:34:04,785] {taskinstance.py:1357} INFO - Starting attempt 1 of 1
[2024-08-25 17:34:04,785] {taskinstance.py:1358} INFO - 
--------------------------------------------------------------------------------
[2024-08-25 17:34:04,809] {taskinstance.py:1377} INFO - Executing <Task(PythonOperator): extrai_dados> on 2022-10-10 00:00:00+00:00
[2024-08-25 17:34:04,815] {standard_task_runner.py:52} INFO - Started process 157618 to run task
[2024-08-25 17:34:04,817] {standard_task_runner.py:79} INFO - Running: ['airflow', 'tasks', 'run', 'dados_climaticos', 'extrai_dados', 'scheduled__2022-10-10T00:00:00+00:00', '--job-id', '35', '--raw', '--subdir', 'DAGS_FOLDER/dados_climaticos.py', '--cfg-path', '/tmp/tmp0qk3wvbh', '--error-file', '/tmp/tmpwy3gp9j4']
[2024-08-25 17:34:04,818] {standard_task_runner.py:80} INFO - Job 35: Subtask extrai_dados
[2024-08-25 17:34:04,882] {task_command.py:370} INFO - Running <TaskInstance: dados_climaticos.extrai_dados scheduled__2022-10-10T00:00:00+00:00 [running]> on host adrilucy.
[2024-08-25 17:34:04,918] {taskinstance.py:1889} ERROR - Task failed with exception
Traceback (most recent call last):
  File "/home/adrilucy/Documentos/airflow-alura/venv/lib/python3.9/site-packages/airflow/models/taskinstance.py", line 1451, in _run_raw_task
    self._execute_task_with_callbacks(context, test_mode)
  File "/home/adrilucy/Documentos/airflow-alura/venv/lib/python3.9/site-packages/airflow/models/taskinstance.py", line 1555, in _execute_task_with_callbacks
    task_orig = self.render_templates(context=context)
  File "/home/adrilucy/Documentos/airflow-alura/venv/lib/python3.9/site-packages/airflow/models/taskinstance.py", line 2212, in render_templates
    rendered_task = self.task.render_template_fields(context)
  File "/home/adrilucy/Documentos/airflow-alura/venv/lib/python3.9/site-packages/airflow/models/baseoperator.py", line 1185, in render_template_fields
    self._do_render_template_fields(self, self.template_fields, context, jinja_env, set())
  File "/home/adrilucy/Documentos/airflow-alura/venv/lib/python3.9/site-packages/airflow/utils/session.py", line 71, in wrapper
    return func(*args, session=session, **kwargs)
  File "/home/adrilucy/Documentos/airflow-alura/venv/lib/python3.9/site-packages/airflow/models/abstractoperator.py", line 344, in _do_render_template_fields
    rendered_content = self.render_template(
  File "/home/adrilucy/Documentos/airflow-alura/venv/lib/python3.9/site-packages/airflow/models/abstractoperator.py", line 404, in render_template
    return {key: self.render_template(value, context, jinja_env) for key, value in value.items()}
  File "/home/adrilucy/Documentos/airflow-alura/venv/lib/python3.9/site-packages/airflow/models/abstractoperator.py", line 404, in <dictcomp>
    return {key: self.render_template(value, context, jinja_env) for key, value in value.items()}
  File "/home/adrilucy/Documentos/airflow-alura/venv/lib/python3.9/site-packages/airflow/models/abstractoperator.py", line 391, in render_template
    return render_template_to_string(template, context)
  File "/home/adrilucy/Documentos/airflow-alura/venv/lib/python3.9/site-packages/airflow/utils/helpers.py", line 296, in render_template_to_string
    return render_template(template, context, native=False)
  File "/home/adrilucy/Documentos/airflow-alura/venv/lib/python3.9/site-packages/airflow/utils/helpers.py", line 291, in render_template
    return "".join(nodes)
  File "<template>", line 12, in root
  File "/home/adrilucy/Documentos/airflow-alura/venv/lib/python3.9/site-packages/jinja2/sandbox.py", line 391, in call
    if not __self.is_safe_callable(__obj):
  File "/home/adrilucy/Documentos/airflow-alura/venv/lib/python3.9/site-packages/jinja2/sandbox.py", line 275, in is_safe_callable
    getattr(obj, "unsafe_callable", False) or getattr(obj, "alters_data", False)
  File "/home/adrilucy/Documentos/airflow-alura/venv/lib/python3.9/site-packages/jinja2/runtime.py", line 910, in __getattr__
    return self._fail_with_undefined_error()
  File "/home/adrilucy/Documentos/airflow-alura/venv/lib/python3.9/site-packages/jinja2/runtime.py", line 903, in _fail_with_undefined_error
    raise self._undefined_exception(self._undefined_message)
jinja2.exceptions.UndefinedError: 'pendulum.datetime.DateTime object' has no attribute 'srtftime'
[2024-08-25 17:34:04,921] {taskinstance.py:1395} INFO - Marking task as FAILED. dag_id=dados_climaticos, task_id=extrai_dados, execution_date=20221010T000000, start_date=20240825T203404, end_date=20240825T203404
[2024-08-25 17:34:04,942] {standard_task_runner.py:92} ERROR - Failed to execute job 35 for task extrai_dados ('pendulum.datetime.DateTime object' has no attribute 'srtftime'; 157618)
[2024-08-25 17:34:04,951] {local_task_job.py:156} INFO - Task exited with return code 1
[2024-08-25 17:34:04,966] {local_task_job.py:273} INFO - 0 downstream tasks scheduled from follow-on schedule check
[2024-08-25 17:41:55,699] {taskinstance.py:1159} INFO - Dependencies all met for <TaskInstance: dados_climaticos.extrai_dados scheduled__2022-10-10T00:00:00+00:00 [queued]>
[2024-08-25 17:41:55,704] {taskinstance.py:1159} INFO - Dependencies all met for <TaskInstance: dados_climaticos.extrai_dados scheduled__2022-10-10T00:00:00+00:00 [queued]>
[2024-08-25 17:41:55,705] {taskinstance.py:1356} INFO - 
--------------------------------------------------------------------------------
[2024-08-25 17:41:55,705] {taskinstance.py:1357} INFO - Starting attempt 1 of 1
[2024-08-25 17:41:55,705] {taskinstance.py:1358} INFO - 
--------------------------------------------------------------------------------
[2024-08-25 17:41:55,720] {taskinstance.py:1377} INFO - Executing <Task(PythonOperator): extrai_dados> on 2022-10-10 00:00:00+00:00
[2024-08-25 17:41:55,725] {standard_task_runner.py:52} INFO - Started process 161737 to run task
[2024-08-25 17:41:55,727] {standard_task_runner.py:79} INFO - Running: ['airflow', 'tasks', 'run', 'dados_climaticos', 'extrai_dados', 'scheduled__2022-10-10T00:00:00+00:00', '--job-id', '37', '--raw', '--subdir', 'DAGS_FOLDER/dados_climaticos.py', '--cfg-path', '/tmp/tmput1d55o1', '--error-file', '/tmp/tmpxmvxmc5c']
[2024-08-25 17:41:55,727] {standard_task_runner.py:80} INFO - Job 37: Subtask extrai_dados
[2024-08-25 17:41:55,761] {task_command.py:370} INFO - Running <TaskInstance: dados_climaticos.extrai_dados scheduled__2022-10-10T00:00:00+00:00 [running]> on host adrilucy.
[2024-08-25 17:41:55,810] {taskinstance.py:1569} INFO - Exporting the following env vars:
AIRFLOW_CTX_DAG_OWNER=airflow
AIRFLOW_CTX_DAG_ID=dados_climaticos
AIRFLOW_CTX_TASK_ID=extrai_dados
AIRFLOW_CTX_EXECUTION_DATE=2022-10-10T00:00:00+00:00
AIRFLOW_CTX_TRY_NUMBER=1
AIRFLOW_CTX_DAG_RUN_ID=scheduled__2022-10-10T00:00:00+00:00
[2024-08-25 17:41:56,652] {python.py:173} INFO - Done. Returned value was: None
[2024-08-25 17:41:56,659] {taskinstance.py:1395} INFO - Marking task as SUCCESS. dag_id=dados_climaticos, task_id=extrai_dados, execution_date=20221010T000000, start_date=20240825T204155, end_date=20240825T204156
[2024-08-25 17:41:56,709] {local_task_job.py:156} INFO - Task exited with return code 0
[2024-08-25 17:41:56,728] {local_task_job.py:273} INFO - 0 downstream tasks scheduled from follow-on schedule check
